<robot name="onshape">
<link name="mainbody">
<visual>
<origin xyz="0 0 0" rpy="0 -0 0" />
<geometry>
<mesh filename="package:///mainbody.stl"/>
</geometry>
<material name="mainbody_material">
<color rgba="0.61568627450980395466 0.81176470588235294379 0.92941176470588238168 1.0"/>
</material>
</visual>
<collision>
<origin xyz="0 0 0" rpy="0 -0 0" />
<geometry>
<mesh filename="package:///mainbody.stl"/>
</geometry>
</collision>
<inertial>
<origin xyz="-3.6572091755492109595e-19 0.060100447946398224963 0.052392477889787354706" rpy="0 0 0"/>
<mass value="1.8998960168588083786" />
<inertia ixx="0.0040164045007738801568" ixy="0"  ixz="0" iyy="0.004048432150908726733" iyz="2.5938108725335605559e-06" izz="0.0045794608158002802351" />
</inertial>
</link>

<link name="motorlegright">
<visual>
<origin xyz="-0.075427325086273797061 0.028000000000000000583 0.063500000000000000888" rpy="1.570796326794896558 1.570796326794896558 0" />
<geometry>
<mesh filename="package:///motorlegright.stl"/>
</geometry>
<material name="motorlegright_material">
<color rgba="0.2313725490196078538 0.38039215686274507888 0.7058823529411765163 1.0"/>
</material>
</visual>
<collision>
<origin xyz="-0.075427325086273797061 0.028000000000000000583 0.063500000000000000888" rpy="1.570796326794896558 1.570796326794896558 0" />
<geometry>
<mesh filename="package:///motorlegright.stl"/>
</geometry>
</collision>
<inertial>
<origin xyz="0.044294085337221025811 0.030476641070772188952 -0.0093160390561676242882" rpy="0 0 0"/>
<mass value="0.079722091407061504431" />
<inertia ixx="5.476833740107948901e-05" ixy="-6.8220333805817399758e-05"  ixz="2.7508370864801470303e-06" iyy="0.00010697913444716319409" iyz="1.892719397873547891e-06" izz="0.00015911531862341235987" />
</inertial>
</link>

<link name="footlegright">
<visual>
<origin xyz="-0.17428686581275198986 -0.040020520487201102777 0.082500000000000003886" rpy="1.570796326794896558 1.570796326794896558 0" />
<geometry>
<mesh filename="package:///footlegright.stl"/>
</geometry>
<material name="footlegright_material">
<color rgba="0.97254901960784312376 0.52941176470588235947 0.0039215686274509803377 1.0"/>
</material>
</visual>
<collision>
<origin xyz="-0.17428686581275198986 -0.040020520487201102777 0.082500000000000003886" rpy="1.570796326794896558 1.570796326794896558 0" />
<geometry>
<mesh filename="package:///footlegright.stl"/>
</geometry>
</collision>
<inertial>
<origin xyz="-0.041569885260259759052 0.036862495599304920257 -0.0095811571760032188116" rpy="0 0 0"/>
<mass value="0.068387458285414134962" />
<inertia ixx="9.1068821727417558582e-05" ixy="9.7715835313104325798e-05"  ixz="-2.7874866833467829843e-06" iyy="0.00011461264217339680845" iyz="2.4718306282221961453e-06" izz="0.0002033312019318689128" />
</inertial>
</link>

<link name="closing_foot_right_1">
<inertial>
<origin xyz="0 0 0" rpy="0 0 0" />
<mass value="1e-9" />
<inertia ixx="0" ixy="0" ixz="0" iyy="0" iyz="0" izz="0" />
</inertial>
</link>
<joint name="closing_foot_right_1_frame" type="fixed">
<origin xyz="0.024937501173317028202 -0.022113569029689604528 0" rpy="0 -0 0" />
<parent link="footlegright" />
<child link="closing_foot_right_1" />
<axis xyz="0 0 0"/>
</joint>

<link name="wheelright">
<visual>
<origin xyz="-0.079512390156467493973 -0.12406269837471399498 0.10150000000000000688" rpy="1.570796326794896558 1.570796326794896558 0" />
<geometry>
<mesh filename="package:///wheelright.stl"/>
</geometry>
<material name="wheelright_material">
<color rgba="0.19607843137254901689 0.19607843137254901689 0.19607843137254901689 1.0"/>
</material>
</visual>
<collision>
<origin xyz="-0.079512390156467493973 -0.12406269837471399498 0.10150000000000000688" rpy="1.570796326794896558 1.570796326794896558 0" />
<geometry>
<mesh filename="package:///wheelright.stl"/>
</geometry>
</collision>
<inertial>
<origin xyz="0 0 -0.006542939615353432492" rpy="0 0 0"/>
<mass value="0.020185364965395396347" />
<inertia ixx="2.9803444742598576856e-06" ixy="0"  ixz="0" iyy="2.9803444742598568386e-06" iyz="0" izz="5.5952390396750311234e-06" />
</inertial>
</link>

<joint name="wheel_right" type="continuous">
<origin xyz="-0.094774475656284495884 0.084042177887512892198 -0.019000000000000002998" rpy="0 -0 0" />
<parent link="footlegright" />
<child link="wheelright" />
<axis xyz="0 0 1"/>
<limit effort="100" velocity="100" />
<joint_properties friction="0.0"/>
</joint>

<joint name="foot_right" type="continuous">
<origin xyz="0.098859540726478192796 0.068020520487201099891 -0.019000000000000086264" rpy="5.5511151231257827021e-17 1.3349865053192493589e-16 8.9958754364216294341e-18" />
<parent link="motorlegright" />
<child link="footlegright" />
<axis xyz="0 0 1"/>
<limit effort="100" velocity="100" />
<joint_properties friction="0.0"/>
</joint>

<joint name="motor_right" type="revolute">
<origin xyz="0.063499999999999945377 0.075427325086273783183 0.027999999999999997113" rpy="-1.570796326794896558 -8.9958754364216371378e-18 1.57079632679489678" />
<parent link="mainbody" />
<child link="motorlegright" />
<axis xyz="0 0 1"/>
<limit effort="100" velocity="100" lower="-0.67055549861622143482" upper="0.67055549861622143482"/>
<joint_properties friction="0.0"/>
</joint>

<link name="supportlegright">
<visual>
<origin xyz="-0.11400000000000000411 0.06657267491372620416 0.063500000000000000888" rpy="1.570796326794896558 1.570796326794896558 0" />
<geometry>
<mesh filename="package:///supportlegright.stl"/>
</geometry>
<material name="supportlegright_material">
<color rgba="0.97254901960784312376 0.52941176470588235947 0.0039215686274509803377 1.0"/>
</material>
</visual>
<collision>
<origin xyz="-0.11400000000000000411 0.06657267491372620416 0.063500000000000000888" rpy="1.570796326794896558 1.570796326794896558 0" />
<geometry>
<mesh filename="package:///supportlegright.stl"/>
</geometry>
</collision>
<inertial>
<origin xyz="0.042612183493034319626 0.042239813185619014269 -0.0094999999999999945599" rpy="0 0 0"/>
<mass value="0.025276933036947005912" />
<inertia ixx="1.9140907407901571136e-05" ixy="-1.8655112587910504873e-05"  ixz="3.401443026570401372e-07" iyy="1.9468383204162914378e-05" iyz="3.371719217987165745e-07" izz="3.790153476767483962e-05" />
</inertial>
</link>

<link name="closing_foot_right_2">
<inertial>
<origin xyz="0 0 0" rpy="0 0 0" />
<mass value="1e-9" />
<inertia ixx="0" ixy="0" ixz="0" iyy="0" iyz="0" izz="0" />
</inertial>
</link>
<joint name="closing_foot_right_2_frame" type="fixed">
<origin xyz="0.085224366986069013952 0.084479626371237709348 -0.019000000000000002998" rpy="0 -0 0" />
<parent link="supportlegright" />
<child link="closing_foot_right_2" />
<axis xyz="0 0 0"/>
</joint>

<joint name="support_right" type="continuous">
<origin xyz="0.063500000000000000888 0.11400000000000000411 0.06657267491372620416" rpy="-1.570796326794896558 -0 1.570796326794896558" />
<parent link="mainbody" />
<child link="supportlegright" />
<axis xyz="0 0 1"/>
<limit effort="100" velocity="100" />
<joint_properties friction="0.0"/>
</joint>

<link name="motorlegleft">
<visual>
<origin xyz="-0.075427325086273797061 -0.028000000000000000583 0.063500000000000000888" rpy="1.570796326794896558 1.570796326794896558 0" />
<geometry>
<mesh filename="package:///motorlegleft.stl"/>
</geometry>
<material name="motorlegleft_material">
<color rgba="0.2313725490196078538 0.38039215686274507888 0.7058823529411765163 1.0"/>
</material>
</visual>
<collision>
<origin xyz="-0.075427325086273797061 -0.028000000000000000583 0.063500000000000000888" rpy="1.570796326794896558 1.570796326794896558 0" />
<geometry>
<mesh filename="package:///motorlegleft.stl"/>
</geometry>
</collision>
<inertial>
<origin xyz="0.044294085337221025811 -0.030476641070772188952 -0.0093160390561676242882" rpy="0 0 0"/>
<mass value="0.079722091407061504431" />
<inertia ixx="5.476833740107948901e-05" ixy="6.8220333805817426863e-05"  ixz="2.7508370864801470303e-06" iyy="0.00010697913444716320764" iyz="-1.8927193978735476792e-06" izz="0.00015911531862341238698" />
</inertial>
</link>

<link name="footlegleft">
<visual>
<origin xyz="-0.17428686581275198986 0.040020520487201102777 0.082500000000000003886" rpy="1.570796326794896558 1.570796326794896558 0" />
<geometry>
<mesh filename="package:///footlegleft.stl"/>
</geometry>
<material name="footlegleft_material">
<color rgba="0.97254901960784312376 0.52941176470588235947 0.0039215686274509803377 1.0"/>
</material>
</visual>
<collision>
<origin xyz="-0.17428686581275198986 0.040020520487201102777 0.082500000000000003886" rpy="1.570796326794896558 1.570796326794896558 0" />
<geometry>
<mesh filename="package:///footlegleft.stl"/>
</geometry>
</collision>
<inertial>
<origin xyz="-0.041569885260259759052 -0.03686249559930490638 -0.0095811571760032049339" rpy="0 0 0"/>
<mass value="0.06838745828541414884" />
<inertia ixx="9.1068821727417572135e-05" ixy="-9.7715835313104325798e-05"  ixz="-2.7874866833467838313e-06" iyy="0.00011461264217339680845" iyz="-2.4718306282221969924e-06" izz="0.0002033312019318689128" />
</inertial>
</link>

<link name="closing_foot_left_1">
<inertial>
<origin xyz="0 0 0" rpy="0 0 0" />
<mass value="1e-9" />
<inertia ixx="0" ixy="0" ixz="0" iyy="0" iyz="0" izz="0" />
</inertial>
</link>
<joint name="closing_foot_left_1_frame" type="fixed">
<origin xyz="0.024937501173317028202 0.022113569029689604528 0" rpy="0 -0 0" />
<parent link="footlegleft" />
<child link="closing_foot_left_1" />
<axis xyz="0 0 0"/>
</joint>

<link name="wheelleft">
<visual>
<origin xyz="-0.079512390156467493973 0.12406269837471399498 0.10150000000000000688" rpy="1.570796326794896558 1.570796326794896558 0" />
<geometry>
<mesh filename="package:///wheelleft.stl"/>
</geometry>
<material name="wheelleft_material">
<color rgba="0.19607843137254901689 0.19607843137254901689 0.19607843137254901689 1.0"/>
</material>
</visual>
<collision>
<origin xyz="-0.079512390156467493973 0.12406269837471399498 0.10150000000000000688" rpy="1.570796326794896558 1.570796326794896558 0" />
<geometry>
<mesh filename="package:///wheelleft.stl"/>
</geometry>
</collision>
<inertial>
<origin xyz="0 0 -0.0065429396153534463698" rpy="0 0 0"/>
<mass value="0.020185364965395399817" />
<inertia ixx="2.9803444742598576856e-06" ixy="0"  ixz="0" iyy="2.9803444742598568386e-06" iyz="0" izz="5.5952390396750311234e-06" />
</inertial>
</link>

<joint name="wheel_left" type="continuous">
<origin xyz="-0.094774475656284495884 -0.084042177887512892198 -0.019000000000000002998" rpy="0 -0 0" />
<parent link="footlegleft" />
<child link="wheelleft" />
<axis xyz="0 0 1"/>
<limit effort="100" velocity="100" />
<joint_properties friction="0.0"/>
</joint>

<joint name="foot_left" type="continuous">
<origin xyz="0.098859540726478192796 -0.068020520487201099891 -0.019000000000000002998" rpy="0 -0 0" />
<parent link="motorlegleft" />
<child link="footlegleft" />
<axis xyz="0 0 1"/>
<limit effort="100" velocity="100" />
<joint_properties friction="0.0"/>
</joint>

<joint name="motor_left" type="revolute">
<origin xyz="-0.063500000000000000888 0.075427325086273797061 0.028000000000000000583" rpy="1.570796326794896558 -0 1.570796326794896558" />
<parent link="mainbody" />
<child link="motorlegleft" />
<axis xyz="0 0 1"/>
<limit effort="100" velocity="100" lower="-0.67055549861622143482" upper="0.67055549861622143482"/>
<joint_properties friction="0.0"/>
</joint>

<link name="supportlegleft">
<visual>
<origin xyz="-0.11400000000000000411 -0.06657267491372620416 0.063500000000000000888" rpy="1.570796326794896558 1.570796326794896558 0" />
<geometry>
<mesh filename="package:///supportlegleft.stl"/>
</geometry>
<material name="supportlegleft_material">
<color rgba="0.97254901960784312376 0.52941176470588235947 0.0039215686274509803377 1.0"/>
</material>
</visual>
<collision>
<origin xyz="-0.11400000000000000411 -0.06657267491372620416 0.063500000000000000888" rpy="1.570796326794896558 1.570796326794896558 0" />
<geometry>
<mesh filename="package:///supportlegleft.stl"/>
</geometry>
</collision>
<inertial>
<origin xyz="0.042612183493034319626 -0.042239813185619014269 -0.0094999999999999945599" rpy="0 0 0"/>
<mass value="0.025276933036947005912" />
<inertia ixx="1.9140907407901577912e-05" ixy="1.8655112587910511649e-05"  ixz="3.401443026570401372e-07" iyy="1.9468383204162917767e-05" iyz="-3.3717192179871636274e-07" izz="3.7901534767674846397e-05" />
</inertial>
</link>

<link name="closing_foot_left_2">
<inertial>
<origin xyz="0 0 0" rpy="0 0 0" />
<mass value="1e-9" />
<inertia ixx="0" ixy="0" ixz="0" iyy="0" iyz="0" izz="0" />
</inertial>
</link>
<joint name="closing_foot_left_2_frame" type="fixed">
<origin xyz="0.085224366986069013952 -0.084479626371237709348 -0.019000000000000002998" rpy="0 -0 0" />
<parent link="supportlegleft" />
<child link="closing_foot_left_2" />
<axis xyz="0 0 0"/>
</joint>

<joint name="support_left" type="continuous">
<origin xyz="-0.063500000000000000888 0.11400000000000000411 0.06657267491372620416" rpy="1.570796326794896558 -0 1.570796326794896558" />
<parent link="mainbody" />
<child link="supportlegleft" />
<axis xyz="0 0 1"/>
<limit effort="100" velocity="100"/>
<joint_properties friction="0.0"/>
</joint>


</robot>
